Validation report for ogc.unstable.sosa.properties.observationCollection - SOSA ObservationCollection
Generated 2023-10-22T04:06:28.515150+00:00
=== Files ===
Using example_1_1.json from examples
=== End Files ===

=== Unknown errors ===

** Validation error **
Traceback (most recent call last):
,  File "/venv/lib/python3.10/site-packages/jsonschema/validators.py", line 909, in resolve_from_url
    document = self.store[url]
,  File "/venv/lib/python3.10/site-packages/jsonschema/_utils.py", line 28, in __getitem__
    return self.store[self.normalize(uri)]
,KeyError: 'file:///github/workspace/registereditems/unstable/ogc-utils/iri-or-curie/schema.yaml'
,
During handling of the above exception, another exception occurred:

,Traceback (most recent call last):
,  File "/usr/local/lib/python3.10/urllib/request.py", line 1505, in open_local_file
    stats = os.stat(localfile)
,FileNotFoundError: [Errno 2] No such file or directory: '/github/workspace/registereditems/unstable/ogc-utils/iri-or-curie/schema.yaml'
,
During handling of the above exception, another exception occurred:

,Traceback (most recent call last):
,  File "/venv/lib/python3.10/site-packages/jsonschema/validators.py", line 912, in resolve_from_url
    document = self.resolve_remote(url)
,  File "/src/ogc/bblocks/validate.py", line 804, in resolve_remote
    with urlopen(uri) as url:
,  File "/usr/local/lib/python3.10/urllib/request.py", line 216, in urlopen
    return opener.open(url, data, timeout)
,  File "/usr/local/lib/python3.10/urllib/request.py", line 519, in open
    response = self._open(req, data)
,  File "/usr/local/lib/python3.10/urllib/request.py", line 536, in _open
    result = self._call_chain(self.handle_open, protocol, protocol +
,  File "/usr/local/lib/python3.10/urllib/request.py", line 496, in _call_chain
    result = func(*args)
,  File "/usr/local/lib/python3.10/urllib/request.py", line 1483, in file_open
    return self.open_local_file(req)
,  File "/usr/local/lib/python3.10/urllib/request.py", line 1522, in open_local_file
    raise URLError(exp)
,urllib.error.URLError: <urlopen error [Errno 2] No such file or directory: '/github/workspace/registereditems/unstable/ogc-utils/iri-or-curie/schema.yaml'>
,
During handling of the above exception, another exception occurred:

,Traceback (most recent call last):
,  File "/src/ogc/bblocks/validate.py", line 476, in validate_inner
    validate_json(json_doc, schema_validator)
,  File "/src/ogc/bblocks/validate.py", line 827, in validate_json
    error = jsonschema.exceptions.best_match(validator.iter_errors(instance))
,  File "/venv/lib/python3.10/site-packages/jsonschema/exceptions.py", line 384, in best_match
    best = next(errors, None)
,  File "/venv/lib/python3.10/site-packages/jsonschema/validators.py", line 288, in iter_errors
    for error in errors:
,  File "/venv/lib/python3.10/site-packages/jsonschema/_validators.py", line 362, in allOf
    yield from validator.descend(instance, subschema, schema_path=index)
,  File "/venv/lib/python3.10/site-packages/jsonschema/validators.py", line 305, in descend
    for error in self.evolve(schema=schema).iter_errors(instance):
,  File "/venv/lib/python3.10/site-packages/jsonschema/validators.py", line 288, in iter_errors
    for error in errors:
,  File "/venv/lib/python3.10/site-packages/jsonschema/_validators.py", line 298, in ref
    yield from validator.descend(instance, resolved)
,  File "/venv/lib/python3.10/site-packages/jsonschema/validators.py", line 305, in descend
    for error in self.evolve(schema=schema).iter_errors(instance):
,  File "/venv/lib/python3.10/site-packages/jsonschema/validators.py", line 288, in iter_errors
    for error in errors:
,  File "/venv/lib/python3.10/site-packages/jsonschema/_validators.py", line 332, in properties
    yield from validator.descend(
,  File "/venv/lib/python3.10/site-packages/jsonschema/validators.py", line 305, in descend
    for error in self.evolve(schema=schema).iter_errors(instance):
,  File "/venv/lib/python3.10/site-packages/jsonschema/validators.py", line 288, in iter_errors
    for error in errors:
,  File "/venv/lib/python3.10/site-packages/jsonschema/_validators.py", line 76, in items
    yield from validator.descend(
,  File "/venv/lib/python3.10/site-packages/jsonschema/validators.py", line 305, in descend
    for error in self.evolve(schema=schema).iter_errors(instance):
,  File "/venv/lib/python3.10/site-packages/jsonschema/validators.py", line 288, in iter_errors
    for error in errors:
,  File "/venv/lib/python3.10/site-packages/jsonschema/_validators.py", line 368, in anyOf
    errs = list(validator.descend(instance, subschema, schema_path=index))
,  File "/venv/lib/python3.10/site-packages/jsonschema/validators.py", line 305, in descend
    for error in self.evolve(schema=schema).iter_errors(instance):
,  File "/venv/lib/python3.10/site-packages/jsonschema/validators.py", line 288, in iter_errors
    for error in errors:
,  File "/venv/lib/python3.10/site-packages/jsonschema/_validators.py", line 294, in ref
    scope, resolved = validator.resolver.resolve(ref)
,  File "/venv/lib/python3.10/site-packages/jsonschema/validators.py", line 898, in resolve
    return url, self._remote_cache(url)
,  File "/venv/lib/python3.10/site-packages/jsonschema/validators.py", line 914, in resolve_from_url
    raise exceptions.RefResolutionError(exc)
,jsonschema.exceptions.RefResolutionError: <urlopen error [Errno 2] No such file or directory: '/github/workspace/registereditems/unstable/ogc-utils/iri-or-curie/schema.yaml'>
,
During handling of the above exception, another exception occurred:

,Traceback (most recent call last):
,  File "/src/ogc/bblocks/validate.py", line 601, in _validate_resource
    validate_inner()
,  File "/src/ogc/bblocks/validate.py", line 496, in validate_inner
    'errorMessage': e.message,
,AttributeError: 'RefResolutionError' object has no attribute 'message'

=== End Unknown errors ===

